= JavaScript Async Patterns
:toc: left
:toclevels: 3
:sectnums:
:source-highlighter: highlight.js

== Purpose
Defines comprehensive standards for asynchronous programming patterns, error handling, and Promise utilities in modern JavaScript applications.

== Related Documentation
* xref:javascript-best-practices.adoc[JavaScript Best Practices]: Complete best practices overview
* xref:javascript-core-patterns.adoc[JavaScript Core Patterns]: Core language patterns and syntax
* xref:javascript-architecture-patterns.adoc[JavaScript Architecture Patterns]: Advanced patterns and organization
* xref:linting-standards.adoc[Linting Standards]: ESLint rules that enforce these practices

== Asynchronous Programming Standards

=== Promise and Async/Await Patterns
Use async/await consistently:

[source,javascript]
----
// Async function - let errors bubble up naturally
const fetchAndProcessData = async (url) => {
  const response = await fetch(url);

  if (!response.ok) {
    throw new Error(`HTTP ${response.status}: ${response.statusText}`);
  }

  const data = await response.json();
  return processData(data);
};

// Alternative: Transform errors meaningfully when caught
const fetchAndProcessDataWithContext = async (url) => {
  try {
    const response = await fetch(url);

    if (!response.ok) {
      throw new Error(`HTTP ${response.status}: ${response.statusText}`);
    }

    const data = await response.json();
    return processData(data);
  } catch (error) {
    // Only catch to add meaningful context or transform the error
    throw new Error(`Failed to fetch and process data from ${url}: ${error.message}`, {
      cause: error
    });
  }
};

// Concurrent operations - let errors bubble up naturally
const fetchMultipleResources = async (urls) => {
  const responses = await Promise.all(
    urls.map(url => fetch(url))
  );

  const data = await Promise.all(
    responses.map(response => response.json())
  );

  return data;
};

// Alternative: Handle partial failures gracefully
const fetchMultipleResourcesWithFallback = async (urls) => {
  const results = await Promise.allSettled(
    urls.map(async (url) => {
      const response = await fetch(url);
      if (!response.ok) {
        throw new Error(`HTTP ${response.status}: ${response.statusText}`);
      }
      return response.json();
    })
  );

  const successful = results
    .filter(result => result.status === 'fulfilled')
    .map(result => result.value);

  const failed = results
    .filter(result => result.status === 'rejected')
    .map((result, index) => ({ url: urls[index], error: result.reason }));

  if (failed.length > 0) {
    console.warn(`${failed.length} requests failed:`, failed);
  }

  return { successful, failed };
};

// Sequential operations when needed
const processItemsSequentially = async (items) => {
  const results = [];

  for (const item of items) {
    const result = await processItem(item);
    results.push(result);
  }

  return results;
};
----

=== Error Handling Standards
Implement comprehensive error handling:

[source,javascript]
----
// Custom error classes
class ValidationError extends Error {
  constructor(field, value, message) {
    super(message);
    this.name = 'ValidationError';
    this.field = field;
    this.value = value;
  }
}

class NetworkError extends Error {
  constructor(url, status, message) {
    super(message);
    this.name = 'NetworkError';
    this.url = url;
    this.status = status;
  }
}

// Better approach: Let errors bubble up naturally
const validateAndSave = async (data) => {
  validateData(data); // Let ValidationError bubble up
  return await saveData(data); // Let NetworkError bubble up
};

// Alternative: Handle errors meaningfully with specific actions
const validateAndSaveWithRecovery = async (data) => {
  try {
    validateData(data);
    return await saveData(data);
  } catch (error) {
    if (error instanceof ValidationError) {
      // Transform validation errors into user-friendly format
      throw new Error(`Invalid ${error.field}: ${error.message}`, {
        cause: error,
        code: 'VALIDATION_FAILED'
      });
    }

    if (error instanceof NetworkError && error.status >= 500) {
      // Only catch server errors to implement retry logic
      console.warn(`Server error (${error.status}), attempting retry...`);
      await new Promise(resolve => setTimeout(resolve, 1000));
      return await saveData(data); // Retry once
    }

    // Let other errors bubble up naturally
    throw error;
  }
};

// Result pattern alternative - avoid throwing altogether
const validateAndSaveResult = async (data) => {
  try {
    validateData(data);
    const result = await saveData(data);
    return { success: true, data: result };
  } catch (error) {
    return { 
      success: false, 
      error: error.message,
      type: error.constructor.name 
    };
  }
};
----

=== Promise Utilities
Use appropriate Promise utilities:

[source,javascript]
----
// Timeout wrapper
const withTimeout = (promise, timeoutMs) => {
  return Promise.race([
    promise,
    new Promise((_, reject) => 
      setTimeout(() => reject(new Error('Operation timed out')), timeoutMs)
    ),
  ]);
};

// Retry logic - legitimate use of catch-and-rethrow
// Note: This is NOT an anti-pattern because catching serves a meaningful purpose
const retryOperation = async (operation, maxRetries = 3, delay = 1000) => {
  let lastError;

  for (let attempt = 1; attempt <= maxRetries; attempt++) {
    try {
      return await operation();
    } catch (error) {
      lastError = error;

      if (attempt === maxRetries) {
        throw error; // Final attempt failed - rethrow is appropriate
      }

      console.warn(`Attempt ${attempt} failed, retrying in ${delay}ms:`, error.message);
      await new Promise(resolve => setTimeout(resolve, delay));
      delay *= 2; // Exponential backoff
    }
  }

  throw lastError; // Safety net - should never reach here
};
----
